# Connection Error Fix Documentation

## Problem

After a task completed successfully, users would see a misleading "Connection Error - Connection error occurred" message. This happened because:

1. When a task completes, the backend SSE stream naturally terminates
2. The browser's EventSource triggers an `onerror` event when the connection closes
3. The frontend treated ALL `onerror` events as connection errors, even when the task completed successfully

## Root Cause Analysis

### Backend Behavior (Expected)
- In `backend/app/api/endpoints/status.py` line 160-162, when a task completes, the server sends a `task_completed` event and terminates the SSE stream
- This is the correct behavior - the stream should end when the task is finished

### Frontend Issue (Fixed)
- In `frontend/src/hooks/useTaskStream.ts`, the `onerror` handler always set error to "Connection error occurred"
- The hook didn't distinguish between:
  - Expected disconnection (task completed successfully)
  - Unexpected disconnection (actual connection error during processing)

## Solution

Modified `useTaskStream.ts` to:

1. **Track expected disconnections**: Added `isDisconnectingRef` to track when we're intentionally disconnecting
2. **Set flag before disconnection**: When a task completes, set `isDisconnectingRef.current = true` before calling `disconnect()`
3. **Conditional error handling**: In the `onerror` handler, only show error message if the disconnection wasn't expected:

```typescript
// Only show error message if this wasn't an expected disconnection
error: isExpectedDisconnect ? null : 'Connection error occurred'
```

4. **Clean up flag**: Reset `isDisconnectingRef.current = false` when disconnecting and connecting

## Code Changes

### File: `frontend/src/hooks/useTaskStream.ts`

1. Added tracking ref:
```typescript
const isDisconnectingRef = useRef<boolean>(false)
```

2. Modified task completion handler:
```typescript
if (['completed', 'failed', 'cancelled'].includes(data.status)) {
  console.log(`Task ${taskId} finished with status: ${data.status}. Disconnecting...`)
  isDisconnectingRef.current = true  // NEW: Mark as expected disconnect
  setTimeout(() => disconnect(), 1000)
}
```

3. Enhanced error handler:
```typescript
eventSource.onerror = (event) => {
  // Check if we're disconnecting because task completed successfully
  const lastStatus = lastStatusRef.current
  const isTaskFinished = lastStatus && ['completed', 'failed', 'cancelled'].includes(lastStatus.status)
  const isExpectedDisconnect = isDisconnectingRef.current || isTaskFinished
  
  updateState({
    isConnected: false,
    isConnecting: false,
    // Only show error message if this wasn't an expected disconnection
    error: isExpectedDisconnect ? null : 'Connection error occurred'
  })
  
  // Auto-reconnect logic (but not for finished tasks or expected disconnects)
  if (autoReconnect && !isTaskFinished && !isExpectedDisconnect && state.connectionAttempts < maxReconnectAttempts) {
    // ... reconnection logic
  }
}
```

## Testing

### Manual Test Scenarios

1. **Successful Task Completion**:
   - Upload image → Task processes → Task completes successfully
   - Expected: No connection error message, only success message
   - Previous: Would show "Connection Error" after success

2. **Task Failure**:
   - Upload invalid image → Task fails
   - Expected: Task error message, no connection error
   - Behavior: Unchanged (still works correctly)

3. **Real Connection Error During Processing**:
   - Upload image → Disconnect network during processing
   - Expected: Shows "Connection error occurred" with retry option
   - Behavior: Unchanged (still works correctly)

4. **Manual Reconnection**:
   - After any error → Click "Retry Connection"
   - Expected: Clears error state and attempts reconnection
   - Behavior: Improved (now clears error state)

### Automated Test Coverage

Created test file: `frontend/src/hooks/__tests__/useTaskStream.test.ts`
- Tests successful completion without error message
- Tests processing error with error message
- Tests failed task without connection error
- Tests manual reconnection error clearing

## User Experience Impact

### Before Fix
```
Task completed successfully! ✅
Connection Error - Connection error occurred ❌
[Retry Connection button]
```

### After Fix
```
Task completed successfully! ✅
[View Results button]
```

## Backward Compatibility

- No breaking changes to API or component interfaces
- Existing error handling for real connection issues remains intact
- No changes to backend SSE implementation
- ProcessingPage component automatically benefits from the fix (no changes needed)

## Edge Cases Handled

1. **Race conditions**: Flag is set before disconnection to avoid timing issues
2. **Manual disconnection**: Flag is reset when connecting/disconnecting manually
3. **Multiple task statuses**: Handles completed, failed, and cancelled states
4. **Reconnection scenarios**: Clears error state when reconnecting manually

## Monitoring

The fix includes enhanced logging:
- Console logs when tasks finish and disconnect intentionally
- Distinguishes between expected and unexpected disconnections in error handler
- Maintains existing debug information for troubleshooting

## Files Modified

1. `frontend/src/hooks/useTaskStream.ts` - Main fix implementation
2. Created `frontend/src/hooks/__tests__/useTaskStream.test.ts` - Test coverage

## Files Not Modified (by design)

- `frontend/src/components/ProcessingPage.tsx` - Already handles null errors correctly
- `backend/app/api/endpoints/status.py` - Backend behavior is correct as-is
- No other frontend components require changes

This fix ensures users see appropriate messages based on the actual state of their tasks, eliminating confusion when tasks complete successfully.